Workbook

Sheet Dashboard
B1: Insider Purchase Event Study
B2: SEC Form 4 open-market buys • 10-Day forward returns • Conviction Sizing
B3: Sample: 2024 • Min trade $10,000 • ~16,000 events • Al Fahad
B5: Events | E5: Avg 10D Returns | H5: Win Rate | L5: Median Return | P5: Unique Tickers
B6: 15916 | E6: 0.0402 | H6: 0.6167 | L6: 0.019 | P6: 1728
D9: 10-Day Return Distribution | M9: Calendar-Time Cumulative Return
E34: Monthly Trade Volume | N34: Mean Return By Insider Role
E57: Top Tickers By Count

Sheet Sheet1
A1: Chart 1 Return Distribution | D1: KPI ROW
A3: <20% | B3: =COUNTIF(Events!L:L,"<-20") -> 400 | D3: Events | E3: =COUNTA(Events!A:A) -> 15916
A4: -20:-10% | B4: =COUNTIFS(Events!L:L,">=-20",Events!L:L,"<-10") -> 1035 | D4: Avg 10d return | E4: =AVERAGE(Events!K:K) -> 0.040181825
A5: -10:-5% | B5: =COUNTIFS(Events!L:L,">=-10",Events!L:L,"<-5") -> 1496 | D5: Win Rate | E5: =COUNTIF(Events!K:K,">0")/COUNT(Events!K:K) -> 0.61671379
A6: -5:0% | B6: =COUNTIFS(Events!L:L,">=-5",Events!L:L,"<0") -> 2996 | D6: Median Return | E6: =MEDIAN(Events!K:K) -> 0.01900504
A7: 0:5% | B7: =COUNTIFS(Events!L:L,">=0",Events!L:L,"<5") -> 4526 | D7: Unique Tickers | E7: =COUNTA(_xlfn.UNIQUE(Events!A:A)) -> 1728
A8: 5:10% | B8: =COUNTIFS(Events!L:L,">=5",Events!L:L,"<10") -> 2276
A9: 10:20% | B9: =COUNTIFS(Events!L:L,">=10",Events!L:L,"<20") -> 1903
A10: 20:50% | B10: =COUNTIFS(Events!L:L,">=20",Events!L:L,"<50") -> 1008
A11: >50% | B11: =COUNTIF(Events!L:L,">=50") -> 275
A14: Chart 2 Large VS Normal
A16: Large Buy Average Return | B16: =AVERAGEIF(Events!J:J,"large_buy",Events!L:L) -> 4.1430989
A17: Normal buy Average Return | B17: =AVERAGEIF(Events!J:J,"normal_buy",Events!L:L) -> 3.9550868
A18: Large Buy Win Rate | B18: =COUNTIFS(Events!J:J,"large_buy",Events!L:L,">0")/COUNTIF(Events!J:J,"large_buy") -> 0.60101105
A19: Normal buy win rate | B19: =COUNTIFS(Events!J:J,"normal_buy",Events!L:L,">0")/COUNTIF(Events!J:J,"normal_buy") -> 0.62464536
A21: Role Breakdown
A22: All Insiders (Director / Officer / 10% Owner) | B22: =AVERAGEIF(Events!F:F,"Director,Officer,TenPercentOwner",Events!K:K) -> 0.089800577
A23: 10% Owners + External | B23: =AVERAGEIF(Events!F:F,"TenPercentOwner,Other",Events!K:K) -> 0.063877995
A24: Management (Directors + Officers) | B24: =AVERAGEIF(Events!F:F,"Director,Officer",Events!K:K) -> 0.049723522
A25: Board + Major Shareholders | B25: =AVERAGEIF(Events!F:F,"Director,TenPercentOwner",Events!K:K) -> 0.048803402
A26: Officers (Executives Only) | B26: =AVERAGEIF(Events!F:F,"Officer",Events!K:K) -> 0.043104205
A27: 10% Owners (Large Shareholders Only) | B27: =AVERAGEIF(Events!F:F,"TenPercentOwner",Events!K:K) -> 0.037430867
A28: Directors (Board Members Only) | B28: =AVERAGEIF(Events!F:F,"Director",Events!K:K) -> 0.036011004
A29: Non-Insider Activity | B29: =AVERAGEIF(Events!F:F,"Other",Events!K:K) -> 0.030598364

Sheet Pivot Monthly
A3: trade_month | B3: Count of ticker
A4: Jan | B4: 1030
A5: Feb | B5: 1662
A6: Mar | B6: 1688
A7: Apr | B7: 961
A8: May | B8: 1567
A9: Jun | B9: 1199
A10: Jul | B10: 1017
A11: Aug | B11: 2006
A12: Sep | B12: 1409
A13: Oct | B13: 1017
A14: Nov | B14: 1419
A15: Dec | B15: 940
A16: Grand Total | B16: 15915

Sheet Pivot Tickers
A3: ticker | B3: Average of ret_10d
A4: CAPR | B4: 3.2871285
A5: MYCB | B5: 2.5499998
A6: TKNO | B6: 2.1875
A7: ANKM | B7: 1.5050001
A8: XCUR | B8: 1.4901961
A9: AASP | B9: 1.4761905
A10: OPTT | B10: 1.4666666
A11: ATLN | B11: 1.3305086
A12: GOVX | B12: 1.1903056
A13: SOWG | B13: 1.0952381
A14: Grand Total | B14: 1.7316815

Sheet Events
A1: ticker | B1: company_name | C1: trade_month | D1: trade_date | E1: insider_name | F1: insider_role | G1: shares | H1: price | I1: value_usd | J1: size_bucket | K1: ret_10d | L1: 10d_return_pct | M1: transaction_type
A2: THW | B2: abrdn World Healthcare Fund | C2: =TEXT(D2, "mmm") -> Jan | D2: 45293 | E2: Reit Todd | F2: Director | G2: 1000 | H2: 11.94 | I2: 11940 | J2: normal_buy | K2: 0.042965509 | L2: 4.2966 | M2: P
A3: LCPMX | B3: Lind Capital Partners Municipal Credit Income Fund | C3: =TEXT(D3, "mmm") -> Jan | D3: 45293 | E3: Adler Richard H | F3: Director | G3: 17179.38 | H3: 8.73 | I3: 149975.99 | J3: large_buy | K3: -0.0011452867 | L3: -0.1145 | M3: P
A4: HPI | B4: JOHN HANCOCK PREFERRED INCOME FUND | C4: =TEXT(D4, "mmm") -> Jan | D4: 45293 | E4: Garfield Dean | F4: Director | G4: 1020.09 | H4: 15.43 | I4: 15739.989 | J4: large_buy | K4: -0.0050956813 | L4: -0.5096 | M4: P
A5: JHI | B5: JOHN HANCOCK INVESTORS TRUST | C5: =TEXT(D5, "mmm") -> Jan | D5: 45293 | E5: Garfield Dean | F5: Director | G5: 1131.46 | H5: 14.41 | I5: 16304.339 | J5: large_buy | K5: 0.0046439175 | L5: 0.4644 | M5: P
A6: JHS | B6: JOHN HANCOCK INCOME SECURITIES TRUST | C6: =TEXT(D6, "mmm") -> Jan | D6: 45293 | E6: Garfield Dean | F6: Director | G6: 1370.44 | H6: 12.01 | I6: 16458.984 | J6: large_buy | K6: 0.0036697987 | L6: 0.367 | M6: P
A7: HEQ | B7: John Hancock Hedged Equity & Income Fund | C7: =TEXT(D7, "mmm") -> Jan | D7: 45293 | E7: Garfield Dean | F7: Director | G7: 1381.25 | H7: 11.63 | I7: 16063.938 | J7: large_buy | K7: -0.0059642376 | L7: -0.5964 | M7: P
A8: BTO | B8: JOHN HANCOCK FINANCIAL OPPORTUNITIES FUND | C8: =TEXT(D8, "mmm") -> Jan | D8: 45293 | E8: Garfield Dean | F8: Director | G8: 512.96 | H8: 30.55 | I8: 15670.928 | J8: large_buy | K8: -0.0217319 | L8: -2.1732 | M8: P
A9: MEGI | B9: MainStay CBRE Global Infrastructure Megatrends Term Fund | C9: =TEXT(D9, "mmm") -> Jan | D9: 45293 | E9: Saba Capital Management, L.P. | F9: TenPercentOwner | G9: 12678 | H9: 13.04 | I9: 165321.12 | J9: normal_buy | K9: 0.02297074 | L9: 2.2971 | M9: P
A10: MEGI | B10: MainStay CBRE Global Infrastructure Megatrends Term Fund | C10: =TEXT(D10, "mmm") -> Jan | D10: 45293 | E10: Weinstein Boaz | F10: TenPercentOwner | G10: 12678 | H10: 13.04 | I10: 165321.12 | J10: normal_buy | K10: 0.02297074 | L10: 2.2971 | M10: P
A11: NQP | B11: NUVEEN PENNSYLVANIA QUALITY MUNICIPAL INCOME FUND | C11: =TEXT(D11, "mmm") -> Jan | D11: 45293 | E11: Weinstein Boaz | F11: TenPercentOwner | G11: 18162 | H11: 11.56 | I11: 209952.72 | J11: normal_buy | K11: -0.00063998734 | L11: -0.064 | M11: P
A12: HTD | B12: JOHN HANCOCK TAX-ADVANTAGED DIVIDEND INCOME FUND | C12: =TEXT(D12, "mmm") -> Jan | D12: 45293 | E12: Garfield Dean | F12: Director | G12: 700.65 | H12: 21.58 | I12: 15120.027 | J12: large_buy | K12: -0.0056540874 | L12: -0.5654 | M12: P
A13: NQP | B13: NUVEEN PENNSYLVANIA QUALITY MUNICIPAL INCOME FUND | C13: =TEXT(D13, "mmm") -> Jan | D13: 45293 | E13: Saba Capital Management, L.P. | F13: TenPercentOwner | G13: 18162 | H13: 11.56 | I13: 209952.72 | J13: normal_buy | K13: -0.00063998734 | L13: -0.064 | M13: P
... A2266: OGN | B2266: Organon & Co. | C2266: =TEXT(D2266, "mmm") -> Feb | D2266: 45344 | E2266: Weaver Kirke | F2266: Officer | G2266: 2720 | H2266: 18.36 | I2266: 49939.2 | J2266: large_buy | K2266: -0.0021893968 | L2266: -0.2189 | M2266: P
A2267: TPL | B2267: Texas Pacific Land Corp | C2267: =TEXT(D2267, "mmm") -> Feb | D2267: 45344 | E2267: HORIZON KINETICS ASSET MANAGEMENT LLC | G2267: 2 | H2267: 105134 | I2267: 210268 | J2267: large_buy | K2267: -0.03734412 | L2267: -3.7344 | M2267: P
A2268: TPL | B2268: Texas Pacific Land Corp | C2268: =TEXT(D2268, "mmm") -> Feb | D2268: 45344 | E2268: STAHL MURRAY | F2268: Director,TenPercentOwner | G2268: 2 | H2268: 105134 | I2268: 210268 | J2268: large_buy | K2268: -0.03734412 | L2268: -3.7344 | M2268: P
A2269: BMEZ | B2269: BlackRock Health Sciences Term Trust | C2269: =TEXT(D2269, "mmm") -> Feb | D2269: 45344 | E2269: Saba Capital Management, L.P. | F2269: TenPercentOwner | G2269: 154932 | H2269: 16.13 | I2269: 2499053.2 | J2269: large_buy | K2269: 0.014197493 | L2269: 1.4197 | M2269: P
A2270: BMEZ | B2270: BlackRock Health Sciences Term Trust | C2270: =TEXT(D2270, "mmm") -> Feb | D2270: 45344 | E2270: Weinstein Boaz | F2270: TenPercentOwner | G2270: 154932 | H2270: 16.13 | I2270: 2499053.2 | J2270: large_buy | K2270: 0.014197493 | L2270: 1.4197 | M2270: P
A2271: BCAT | B2271: BlackRock Capital Allocation Term Trust | C2271: =TEXT(D2271, "mmm") -> Feb | D2271: 45344 | E2271: Weinstein Boaz | F2271: TenPercentOwner | G2271: 126947 | H2271: 15.51 | I2271: 1968948 | J2271: large_buy | K2271: 0.018029823 | L2271: 1.803 | M2271: P
A2272: BCAT | B2272: BlackRock Capital Allocation Term Trust | C2272: =TEXT(D2272, "mmm") -> Feb | D2272: 45344 | E2272: Saba Capital Management, L.P. | F2272: TenPercentOwner | G2272: 126947 | H2272: 15.51 | I2272: 1968948 | J2272: large_buy | K2272: 0.018029823 | L2272: 1.803 | M2272: P
A2273: ECAT | B2273: BlackRock ESG Capital Allocation Term Trust | C2273: =TEXT(D2273, "mmm") -> Feb | D2273: 45344 | E2273: Weinstein Boaz | F2273: TenPercentOwner | G2273: 43233 | H2273: 16.96 | I2273: 733231.68 | J2273: normal_buy | K2273: 0.0076557831 | L2273: 0.7656 | M2273: P
A2274: CART | B2274: Maplebear Inc. | C2274: =TEXT(D2274, "mmm") -> Feb | D2274: 45344 | E2274: SEQUOIA CAPITAL U.S. VENTURE PARTNERS FUND XIV, L.P. | F2274: TenPercentOwner | G2274: 203213 | H2274: 29.95 | I2274: 6086229.3 | J2274: normal_buy | K2274: 0.15093709 | L2274: 15.0937 | M2274: P
A2275: CART | B2275: Maplebear Inc. | C2275: =TEXT(D2275, "mmm") -> Feb | D2275: 45344 | E2275: SEQUOIA CAPITAL U.S. VENTURE FUND XIV, L.P. | F2275: TenPercentOwner | G2275: 203213 | H2275: 29.95 | I2275: 6086229.3 | J2275: normal_buy | K2275: 0.15093709 | L2275: 15.0937 | M2275: P
A2276: CART | B2276: Maplebear Inc. | C2276: =TEXT(D2276, "mmm") -> Feb | D2276: 45344 | E2276: Sequoia Capital Global Growth Fund III - Endurance Partners, L.P. | F2276: TenPercentOwner | G2276: 203213 | H2276: 29.95 | I2276: 6086229.3 | J2276: normal_buy | K2276: 0.15093709 | L2276: 15.0937 | M2276: P
A2277: CART | B2277: Maplebear Inc. | C2277: =TEXT(D2277, "mmm") -> Feb | D2277: 45344 | E2277: SC Global Growth II Management, L.P. | F2277: TenPercentOwner | G2277: 203213 | H2277: 29.95 | I2277: 6086229.3 | J2277: normal_buy | K2277: 0.15093709 | L2277: 15.0937 | M2277: P
A2278: CART | B2278: Maplebear Inc. | C2278: =TEXT(D2278, "mmm") -> Feb | D2278: 45344 | E2278: SC US (TTGP), LTD. | F2278: TenPercentOwner | G2278: 203213 | H2278: 29.95 | I2278: 6086229.3 | J2278: normal_buy | K2278: 0.15093709 | L2278: 15.0937 | M2278: P
A2279: CART | B2279: Maplebear Inc. | C2279: =TEXT(D2279, "mmm") -> Feb | D2279: 45344 | E2279: SC U.S. VENTURE XIV MANAGEMENT, L.P. | F2279: TenPercentOwner | G2279: 203213 | H2279: 29.95 | I2279: 6086229.3 | J2279: normal_buy | K2279: 0.15093709 | L2279: 15.0937 | M2279: P
... A7231: OEC | B7231: Orion S.A. | C7231: =TEXT(D7231, "mmm") -> Jun | D7231: 45450 | E7231: Glajch Jeffrey | F7231: Officer | G7231: 5000 | H7231: 23.68 | I7231: 118400 | J7231: large_buy | K7231: -0.044137791 | L7231: -4.4138 | M7231: P
A7232: AFB | B7232: ALLIANCEBERNSTEIN NATIONAL MUNICIPAL INCOME FUND | C7232: =TEXT(D7232, "mmm") -> Jun | D7232: 45450 | E7232: BOFA SECURITIES, INC. | G7232: 1600 | H7232: 10.87 | I7232: 17392 | J7232: normal_buy | K7232: 0.014692235 | L7232: 1.4692 | M7232: P
A7233: AFB | B7233: ALLIANCEBERNSTEIN NATIONAL MUNICIPAL INCOME FUND | C7233: =TEXT(D7233, "mmm") -> Jun | D7233: 45450 | E7233: BANK OF AMERICA CORP /DE/ | F7233: TenPercentOwner,Other | G7233: 1600 | H7233: 10.87 | I7233: 17392 | J7233: normal_buy | K7233: 0.014692235 | L7233: 1.4692 | M7233: P
A7234: AFB | B7234: ALLIANCEBERNSTEIN NATIONAL MUNICIPAL INCOME FUND | C7234: =TEXT(D7234, "mmm") -> Jun | D7234: 45450 | E7234: Banc of America Preferred Funding Corp | F7234: TenPercentOwner | G7234: 1600 | H7234: 10.87 | I7234: 17392 | J7234: normal_buy | K7234: 0.014692235 | L7234: 1.4692 | M7234: P
A7235: CDTX | B7235: Cidara Therapeutics, Inc. | C7235: =TEXT(D7235, "mmm") -> Jun | D7235: 45450 | E7235: Stein Jeffrey | F7235: Director,Officer | G7235: 8000 | H7235: 13.21 | I7235: 105680 | J7235: large_buy | K7235: -0.12071652 | L7235: -12.0717 | M7235: P
A7236: ALTG | B7236: ALTA EQUIPMENT GROUP INC. | C7236: =TEXT(D7236, "mmm") -> Jun | D7236: 45450 | E7236: Hoover Jeffrey Alan | F7236: Officer | G7236: 4000 | H7236: 8.17 | I7236: 32680 | J7236: normal_buy | K7236: 0.02267303 | L7236: 2.2673 | M7236: P
A7237: PBF | B7237: PBF Energy Inc. | C7237: =TEXT(D7237, "mmm") -> Jun | D7237: 45450 | E7237: Control Empresarial de Capitales S.A. de C.V. | F7237: TenPercentOwner,Other | G7237: 51000 | H7237: 46.19 | I7237: 2355690 | J7237: normal_buy | K7237: -0.040000105 | L7237: -4 | M7237: P
A7238: GBDC | B7238: GOLUB CAPITAL BDC, Inc. | C7238: =TEXT(D7238, "mmm") -> Jun | D7238: 45450 | E7238: Golub Lawrence E | F7238: Director,Officer | G7238: 62267 | H7238: 16.06 | I7238: 1000008 | J7238: large_buy | K7238: -0.016220787 | L7238: -1.6221 | M7238: P
A7239: CAPIX | B7239: Calamos Aksia Alternative Credit & Income Fund | C7239: =TEXT(D7239, "mmm") -> Jun | D7239: 45450 | E7239: Behan Robert | F7239: Officer | G7239: 2349.62 | H7239: 10.64 | I7239: 24999.957 | J7239: normal_buy | K7239: 0.0028193952 | L7239: 0.2819 | M7239: P
A7240: HQL | B7240: abrdn Life Sciences Investors | C7240: =TEXT(D7240, "mmm") -> Jun | D7240: 45450 | E7240: Weinstein Boaz | F7240: TenPercentOwner | G7240: 3763 | H7240: 13.72 | I7240: 51628.36 | J7240: normal_buy | K7240: 0.029069578 | L7240: 2.907 | M7240: P
A7241: HQL | B7241: abrdn Life Sciences Investors | C7241: =TEXT(D7241, "mmm") -> Jun | D7241: 45450 | E7241: Saba Capital Management, L.P. | F7241: TenPercentOwner | G7241: 3763 | H7241: 13.72 | I7241: 51628.36 | J7241: normal_buy | K7241: 0.029069578 | L7241: 2.907 | M7241: P
A7242: SNOW | B7242: Snowflake Inc. | C7242: =TEXT(D7242, "mmm") -> Jun | D7242: 45450 | E7242: Speiser Michael L | F7242: Director | G7242: 76200 | H7242: 131.09 | I7242: 9989058 | J7242: large_buy | K7242: -0.048853009 | L7242: -4.8853 | M7242: P
A7243: LDI | B7243: loanDepot, Inc. | C7243: =TEXT(D7243, "mmm") -> Jun | D7243: 45450 | E7243: Martell Frank | F7243: Director,Officer | G7243: 25000 | H7243: 2.09 | I7243: 52250 | J7243: normal_buy | K7243: -0.14903844 | L7243: -14.9038 | M7243: P
...

Sheet Summary
A1: size_bucket | B1: count | C1: mean | D1: median | E1: mean_return_pct | F1: median_return_pct
A2: large_buy | B2: 5341 | C2: 0.041430987 | D2: 0.01718015 | E2: 4.1431 | F2: 1.718
A3: normal_buy | B3: 10574 | C3: 0.039550865 | D3: 0.020101129 | E3: 3.9551 | F3: 2.0101
A4: Total Events | B4: =SUM(Table7[count]) -> 15915 | C4: =SUM(Table7[mean]) -> 0.080981852 | D4: =SUM(Table7[median]) -> 0.037281279 | E4: =SUM(Table7[mean_return_pct]) -> 8.0982 | F4: =SUM(Table7[median_return_pct]) -> 3.7281

Sheet Calendar Equity
A1: date | B1: Month | C1: cumulative_return
A2: 45303 | B2: =TEXT(A2, "mmm") -> Jan | C2: 1.0818961
A3: 45304 | B3: =TEXT(A3, "mmm") -> Jan | C3: 1.0730942
A4: 45305 | B4: =TEXT(A4, "mmm") -> Jan | C4: 1.0600536
A5: 45306 | B5: =TEXT(A5, "mmm") -> Jan | C5: 1.0754196
A6: 45309 | B6: =TEXT(A6, "mmm") -> Jan | C6: 1.0455366 | E6: Month | F6: Sum of cumulative_return
A7: 45310 | B7: =TEXT(A7, "mmm") -> Jan | C7: 1.0313316 | E7: Jan | F7: 15.228166
A8: 45311 | B8: =TEXT(A8, "mmm") -> Jan | C8: 1.022047 | E8: Feb | F8: 53.995138
A9: 45312 | B9: =TEXT(A9, "mmm") -> Jan | C9: 1.0524241 | E9: Mar | F9: 258.5879
A10: 45313 | B10: =TEXT(A10, "mmm") -> Jan | C10: 1.1299385 | E10: Apr | F10: 416.02137
A11: 45317 | B11: =TEXT(A11, "mmm") -> Jan | C11: 1.2260551 | E11: May | F11: 708.54351
A12: 45318 | B12: =TEXT(A12, "mmm") -> Jan | C12: 1.2927658 | E12: Jun | F12: 947.66696
A13: 45319 | B13: =TEXT(A13, "mmm") -> Jan | C13: 1.4040213 | E13: Jul | F13: 2896.1687
A14: 45320 | B14: =TEXT(A14, "mmm") -> Jan | C14: 1.7335824 | E14: Aug | F14: 3099.7143
A15: 45323 | B15: =TEXT(A15, "mmm") -> Feb | C15: 1.8069218 | E15: Sep | F15: 6935.2075
A16: 45324 | B16: =TEXT(A16, "mmm") -> Feb | C16: 1.8098482 | E16: Oct | F16: 15109.37
A17: 45325 | B17: =TEXT(A17, "mmm") -> Feb | C17: 1.9405622 | E17: Nov | F17: 47192.405
A18: 45326 | B18: =TEXT(A18, "mmm") -> Feb | C18: 2.2428055 | E18: Dec | F18: 74137.454
A19: 45327 | B19: =TEXT(A19, "mmm") -> Feb | C19: 1.9913499 | E19: Grand Total | F19: 151770.36
A20: 45330 | B20: =TEXT(A20, "mmm") -> Feb | C20: 2.1457925
A21: 45331 | B21: =TEXT(A21, "mmm") -> Feb | C21: 2.1308228
A22: 45332 | B22: =TEXT(A22, "mmm") -> Feb | C22: 2.1400011
A23: 45333 | B23: =TEXT(A23, "mmm") -> Feb | C23: 2.2049244
A24: 45334 | B24: =TEXT(A24, "mmm") -> Feb | C24: 2.2109709
A25: 45337 | B25: =TEXT(A25, "mmm") -> Feb | C25: 2.2456366
A26: 45338 | B26: =TEXT(A26, "mmm") -> Feb | C26: 2.0931842
A27: 45339 | B27: =TEXT(A27, "mmm") -> Feb | C27: 2.1040356
A28: 45340 | B28: =TEXT(A28, "mmm") -> Feb | C28: 2.4786231
A29: 45341 | B29: =TEXT(A29, "mmm") -> Feb | C29: 3.1703047
A30: 45344 | B30: =TEXT(A30, "mmm") -> Feb | C30: 3.4803849
A31: 45345 | B31: =TEXT(A31, "mmm") -> Feb | C31: 4.3472006
... A251: 45652 | B251: =TEXT(A251, "mmm") -> Dec | C251: 4050.3423

Sheet Parameters
A1: parameter | B1: value
A2: min_value_usd | B2: 10000
A3: start_date | B3: 2024-01-01
A4: end_date | B4: 2025-01-01
A5: large_buy_quantile | B5: 0.75
A6: forward_horizon_days | B6: 10
A7: generated_at | B7: 2026-06-01T11:13:54
